<?xml version="1.0" encoding="utf-8"?>
<!-- This URDF was automatically created by SolidWorks to URDF Exporter! Originally created by Stephen Brawner (brawner@gmail.com) 
     Commit Version: 1.6.0-4-g7f85cfe  Build Version: 1.6.7995.38578
     For more information, please see http://wiki.ros.org/sw_urdf_exporter -->
<robot
  name="octobot_2">
  <link
    name="base_link">
    <inertial>
      <origin
        xyz="9.36750677027476E-17 -1.38777878078145E-16 0.0219078321663383"
        rpy="0 0 0" />
      <mass
        value="1.1175650125318" />
      <inertia
        ixx="0.0114472292324545"
        ixy="2.61224960933226E-18"
        ixz="4.17609475120386E-20"
        iyy="0.0114472292324545"
        iyz="4.02254469121529E-20"
        izz="0.0227792283886872" />
    </inertial>
    <visual>
      <origin
        xyz="0 0 0"
        rpy="0 0 0" />
      <geometry>
        <mesh
          filename="package://octobot_2/meshes/base_link.STL" />
      </geometry>
      <material
        name="">
        <color
          rgba="0.792156862745098 0.819607843137255 0.933333333333333 1" />
      </material>
    </visual>
    <collision>
      <origin
        xyz="0 0 0"
        rpy="0 0 0" />
      <geometry>
        <mesh
          filename="package://octobot_2/meshes/base_link.STL" />
      </geometry>
    </collision>
  </link>
    <joint name="Base_footprint_joint" type="fixed">
        <parent link="base_link"/>
        <child link="base_footprint"/>
        <origin xyz="0 0 0" rpy="0 0 0"/>
    </joint>
    <link name="base_footprint">
    </link>
    
  <link
    name="fl_link">
    <inertial>
      <origin
        xyz="9.2181E-07 -1.2E-07 -0.0070104"
        rpy="0 0 0" />
      <mass
        value="0.088298" />
      <inertia
        ixx="3.4213E-05"
        ixy="4.4775E-10"
        ixz="-8.2831E-11"
        iyy="3.4217E-05"
        iyz="-6.5931E-11"
        izz="6.4363E-05" />
    </inertial>
    <visual>
      <origin
        xyz="0 0 0"
        rpy="0 0 0" />
      <geometry>
        <mesh
          filename="package://octobot_2/meshes/fl_link.STL" />
      </geometry>
      <material
        name="">
        <color
          rgba="0.39216 0.41961 0.53333 1" />
      </material>
    </visual>
    <collision>
      <origin
        xyz="0 0 0"
        rpy="0 0 0" />
      <geometry>
        <mesh
          filename="package://octobot_2/meshes/fl_link.STL" />
      </geometry>
    </collision>
  </link>
  <joint
    name="fl_joint"
    type="continuous">
    <origin
      xyz="0.204059140837111 0.204058568909617 0.0185006014174271"
      rpy="1.5707963267949 0 2.35619449019235" />
    <parent
      link="base_link" />
    <child
      link="fl_link" />
    <axis
      xyz="0 0 -1" />
  </joint>
  <link
    name="bl_link">
    <inertial>
      <origin
        xyz="9.2186E-07 -1.2049E-07 -0.0070104"
        rpy="0 0 0" />
      <mass
        value="0.088298" />
      <inertia
        ixx="3.4213E-05"
        ixy="4.4798E-10"
        ixz="-8.2849E-11"
        iyy="3.4217E-05"
        iyz="-6.5977E-11"
        izz="6.4363E-05" />
    </inertial>
    <visual>
      <origin
        xyz="0 0 0"
        rpy="0 0 0" />
      <geometry>
        <mesh
          filename="package://octobot_2/meshes/bl_link.STL" />
      </geometry>
      <material
        name="">
        <color
          rgba="0.39216 0.41961 0.53333 1" />
      </material>
    </visual>
    <collision>
      <origin
        xyz="0 0 0"
        rpy="0 0 0" />
      <geometry>
        <mesh
          filename="package://octobot_2/meshes/bl_link.STL" />
      </geometry>
    </collision>
  </link>
  <joint
    name="bl_joint"
    type="continuous">
    <origin
      xyz="-0.20405856891013 0.204059140837137 0.0185006014175988"
      rpy="1.5707963267949 0 -2.35619449019234" />
    <parent
      link="base_link" />
    <child
      link="bl_link" />
    <axis
      xyz="0 0 -1" />
  </joint>
  <link
    name="br_link">
    <inertial>
      <origin
        xyz="-2.7675E-07 1.7255E-07 -0.0069896"
        rpy="0 0 0" />
      <mass
        value="0.088298" />
      <inertia
        ixx="3.4213E-05"
        ixy="-4.4778E-10"
        ixz="-8.2871E-11"
        iyy="3.4217E-05"
        iyz="6.5947E-11"
        izz="6.4363E-05" />
    </inertial>
    <visual>
      <origin
        xyz="0 0 0"
        rpy="0 0 0" />
      <geometry>
        <mesh
          filename="package://octobot_2/meshes/br_link.STL" />
      </geometry>
      <material
        name="">
        <color
          rgba="0.39216 0.41961 0.53333 1" />
      </material>
    </visual>
    <collision>
      <origin
        xyz="0 0 0"
        rpy="0 0 0" />
      <geometry>
        <mesh
          filename="package://octobot_2/meshes/br_link.STL" />
      </geometry>
    </collision>
  </link>
  <joint
    name="br_joint"
    type="continuous">
    <origin
      xyz="-0.20406 -0.20406 0.0185"
      rpy="1.5708 0 -0.7854" />
    <parent
      link="base_link" />
    <child
      link="br_link" />
    <axis
      xyz="0 0 -1" />
  </joint>
  <link
    name="fr_link">
    <inertial>
      <origin
        xyz="-2.7674E-07 1.7255E-07 -0.0069896"
        rpy="0 0 0" />
      <mass
        value="0.088298" />
      <inertia
        ixx="3.4213E-05"
        ixy="-4.4778E-10"
        ixz="-8.2864E-11"
        iyy="3.4217E-05"
        iyz="6.5947E-11"
        izz="6.4363E-05" />
    </inertial>
    <visual>
      <origin
        xyz="0 0 0"
        rpy="0 0 0" />
      <geometry>
        <mesh
          filename="package://octobot_2/meshes/fr_link.STL" />
      </geometry>
      <material
        name="">
        <color
          rgba="0.39216 0.41961 0.53333 1" />
      </material>
    </visual>
    <collision>
      <origin
        xyz="0 0 0"
        rpy="0 0 0" />
      <geometry>
        <mesh
          filename="package://octobot_2/meshes/fr_link.STL" />
      </geometry>
    </collision>
  </link>
  <joint
    name="fr_joint"
    type="continuous">
    <origin
      xyz="0.20406 -0.20406 0.0185"
      rpy="1.5708 0 0.7854" />
    <parent
      link="base_link" />
    <child
      link="fr_link" />
    <axis
      xyz="0 0 -1" />
  </joint>
  <link
    name="lidar_link">
    <inertial>
      <origin
        xyz="5.2042E-18 0 -0.025"
        rpy="0 0 0" />
      <mass
        value="0.19242" />
      <inertia
        ixx="9.9017E-05"
        ixy="-6.1175E-53"
        ixz="-2.8234E-21"
        iyy="9.9017E-05"
        iyz="3.2537E-37"
        izz="0.00011786" />
    </inertial>
    <visual>
      <origin
        xyz="0 0 0"
        rpy="0 0 0" />
      <geometry>
        <mesh
          filename="package://octobot_2/meshes/lidar_link.STL" />
      </geometry>
      <material
        name="">
        <color
          rgba="0.3 0.3 0.3 1" />
      </material>
    </visual>
    <collision>
      <origin
        xyz="0 0 0"
        rpy="0 0 0" />
      <geometry>
        <mesh
          filename="package://octobot_2/meshes/lidar_link.STL" />
      </geometry>
    </collision>
  </link>
  <joint
    name="lidar_joint"
    type="fixed">
    <origin
      xyz="0 0 0.093"
      rpy="0 0 0" />
    <parent
      link="base_link" />
    <child
      link="lidar_link" />
    <axis
      xyz="0 0 0" />
  </joint>

  <gazebo reference="lidar_link">
    <material>Gazebo/Black</material>

    <sensor name="laser" type="ray">
        <pose> 0 0 0 0 0 0 </pose>
        <visualize>true</visualize>
        <update_rate>10</update_rate>
        <ray>
            <scan>
                <horizontal>
                    <samples>360</samples>
                    <min_angle>-3.14</min_angle>
                    <max_angle>3.14</max_angle>
                </horizontal>
            </scan>
            <range>
                <min>0.05</min>
                <max>12</max>
            </range>
        </ray>
        <plugin name="laser_controller" filename="libgazebo_ros_ray_sensor.so">
            <ros>
                <argument>~/out:=scan</argument>
            </ros>
            <output_type>sensor_msgs/LaserScan</output_type>
            <frame_name>base_link</frame_name>
        </plugin>
    </sensor>
</gazebo>

  <!-- <link
    name="cam_link">
    <inertial>
      <origin
        xyz="0 0 -0.015"
        rpy="0 0 0" />
      <mass
        value="0.135" />
      <inertia
        ixx="0.00026325"
        ixy="-8.8986E-22"
        ixz="-5.294E-22"
        iyy="2.025E-05"
        iyz="-2.6698E-21"
        izz="0.00026325" />
    </inertial>
    <visual>
      <origin
        xyz="0 0 0"
        rpy="0 0 0" />
      <geometry>
        <mesh
          filename="package://octobot_2/meshes/cam_link.STL" />
      </geometry>
      <material
        name="">
        <color
          rgba="0.1 0.1 0.1 1" />
      </material>
    </visual>
    <collision>
      <origin
        xyz="0 0 0"
        rpy="0 0 0" />
      <geometry>
        <mesh
          filename="package://octobot_2/meshes/cam_link.STL" />
      </geometry>
    </collision>
  </link>
  <joint
    name="cam_joint"
    type="fixed">
    <origin
      xyz="0.239 0 0.073"
      rpy="0 0 0" />
    <parent
      link="base_link" />
    <child
      link="cam_link" />
    <axis
      xyz="0 0 0" />
  </joint>

  <gazebo reference="cam_link">
    <material>Gazebo/Black</material>

    <sensor name="camera" type="camera">
        <pose> 0 0 0 0 0 0 </pose>
        <visualize>true</visualize>
        <update_rate>10</update_rate>
        <camera>
            <horizontal_fov>1.089</horizontal_fov>
            <image>
                <format>R8G8B8</format>
                <width>640</width>
                <height>480</height>
            </image>
            <clip>
                <near>0.05</near>
                <far>8.0</far>
            </clip>
        </camera>
        <plugin name="camera_controller" filename="libgazebo_ros_camera.so">
            <frame_name>base_link</frame_name>
        </plugin>
    </sensor>
</gazebo> -->
<gazebo reference="base_link">
  <turnGravityOff>true</turnGravityOff>
</gazebo>
<gazebo reference="fl_link">
  <turnGravityOff>true</turnGravityOff>
</gazebo>
<gazebo reference="fr_link">
  <turnGravityOff>true</turnGravityOff>
</gazebo>
<gazebo reference="br_link">
  <turnGravityOff>true</turnGravityOff>
</gazebo>
<gazebo reference="bl_link">
  <turnGravityOff>true</turnGravityOff>
</gazebo>
<gazebo reference="lidar_link">
  <turnGravityOff>true</turnGravityOff>
</gazebo>
<gazebo>
  <plugin name="omni_drive" filename="libgazebo_ros_planar_move.so">
      <!-- Output -->
      <odometry_frame>odom</odometry_frame>
      <robot_base_frame>base_link </robot_base_frame>

      <publish_odom>true</publish_odom>
      <publish_odom_tf>true</publish_odom_tf>
      <publish_wheel_tf>true</publish_wheel_tf>

  </plugin>
</gazebo>


</robot>