<?xml version="1.0" encoding="utf-8"?>
<!-- This URDF was automatically created by SolidWorks to URDF Exporter! Originally created by Stephen Brawner (brawner@gmail.com) 
     Commit Version: 1.6.0-4-g7f85cfe  Build Version: 1.6.7995.38578
     For more information, please see http://wiki.ros.org/sw_urdf_exporter -->
<robot
  name="NuevaBaseMetal2">
  <link
    name="Base_link">
    <inertial>
      <origin
        xyz="7.1124E-17 -8.3267E-17 0.021908"
        rpy="0 0 0" />
      <mass
        value="1.1176" />
      <inertia
        ixx="0.011447"
        ixy="2.575E-18"
        ixz="4.0437E-20"
        iyy="0.011447"
        iyz="2.4119E-20"
        izz="0.022779" />
    </inertial>
    <visual>
      <origin
        xyz="0 0 0"
        rpy="0 0 0" />
      <geometry>
        <mesh
          filename="package://NuevaBaseMetal2/meshes/Base_link.STL" />
      </geometry>
      <material
        name="">
        <color
          rgba="0.79216 0.81961 0.93333 1" />
      </material>
    </visual>
    <collision>
      <origin
        xyz="0 0 0"
        rpy="0 0 0" />
      <geometry>
        <mesh
          filename="package://NuevaBaseMetal2/meshes/Base_link.STL" />
      </geometry>
    </collision>
  </link>
  <link
    name="FL_Link">
    <inertial>
      <origin
        xyz="9.2184E-07 -1.2007E-07 -0.0070104"
        rpy="0 0 0" />
      <mass
        value="0.088298" />
      <inertia
        ixx="3.4213E-05"
        ixy="4.4784E-10"
        ixz="-8.2869E-11"
        iyy="3.4217E-05"
        iyz="-6.5929E-11"
        izz="6.4363E-05" />
    </inertial>
    <visual>
      <origin
        xyz="0 0 0"
        rpy="0 0 0" />
      <geometry>
        <mesh
          filename="package://NuevaBaseMetal2/meshes/FL_Link.STL" />
      </geometry>
      <material
        name="">
        <color
          rgba="0.39216 0.41961 0.53333 1" />
      </material>
    </visual>
    <collision>
      <origin
        xyz="0 0 0"
        rpy="0 0 0" />
      <geometry>
        <mesh
          filename="package://NuevaBaseMetal2/meshes/FL_Link.STL" />
      </geometry>
    </collision>
  </link>
  <joint
    name="FL_Joint"
    type="continuous">
    <origin
      xyz="0.20406 0.20406 0.018501"
      rpy="1.5708 0 2.3562" />
    <parent
      link="Base_link" />
    <child
      link="FL_Link" />
    <axis
      xyz="0 0 -1" />
  </joint>
  <link
    name="BL_Link">
    <inertial>
      <origin
        xyz="9.2186E-07 -1.2049E-07 -0.0070104"
        rpy="0 0 0" />
      <mass
        value="0.088298" />
      <inertia
        ixx="3.4213E-05"
        ixy="4.4798E-10"
        ixz="-8.2849E-11"
        iyy="3.4217E-05"
        iyz="-6.5977E-11"
        izz="6.4363E-05" />
    </inertial>
    <visual>
      <origin
        xyz="0 0 0"
        rpy="0 0 0" />
      <geometry>
        <mesh
          filename="package://NuevaBaseMetal2/meshes/BL_Link.STL" />
      </geometry>
      <material
        name="">
        <color
          rgba="0.39216 0.41961 0.53333 1" />
      </material>
    </visual>
    <collision>
      <origin
        xyz="0 0 0"
        rpy="0 0 0" />
      <geometry>
        <mesh
          filename="package://NuevaBaseMetal2/meshes/BL_Link.STL" />
      </geometry>
    </collision>
  </link>
  <joint
    name="BL_Joint"
    type="continuous">
    <origin
      xyz="-0.20406 0.20406 0.018501"
      rpy="1.5708 0 -2.3562" />
    <parent
      link="Base_link" />
    <child
      link="BL_Link" />
    <axis
      xyz="0 0 -1" />
  </joint>
  <link
    name="BR_Link">
    <inertial>
      <origin
        xyz="-2.7677E-07 1.7253E-07 -0.0069896"
        rpy="0 0 0" />
      <mass
        value="0.088298" />
      <inertia
        ixx="3.4213E-05"
        ixy="-4.4778E-10"
        ixz="-8.2879E-11"
        iyy="3.4217E-05"
        iyz="6.5933E-11"
        izz="6.4363E-05" />
    </inertial>
    <visual>
      <origin
        xyz="0 0 0"
        rpy="0 0 0" />
      <geometry>
        <mesh
          filename="package://NuevaBaseMetal2/meshes/BR_Link.STL" />
      </geometry>
      <material
        name="">
        <color
          rgba="0.39216 0.41961 0.53333 1" />
      </material>
    </visual>
    <collision>
      <origin
        xyz="0 0 0"
        rpy="0 0 0" />
      <geometry>
        <mesh
          filename="package://NuevaBaseMetal2/meshes/BR_Link.STL" />
      </geometry>
    </collision>
  </link>
  <joint
    name="BR_Joint"
    type="continuous">
    <origin
      xyz="-0.20406 -0.20406 0.0185"
      rpy="1.5708 0 -0.7854" />
    <parent
      link="Base_link" />
    <child
      link="BR_Link" />
    <axis
      xyz="0 0 -1" />
  </joint>
  <link
    name="FR_Link">
    <inertial>
      <origin
        xyz="-2.7674E-07 1.7255E-07 -0.0069896"
        rpy="0 0 0" />
      <mass
        value="0.088298" />
      <inertia
        ixx="3.4213E-05"
        ixy="-4.4778E-10"
        ixz="-8.2864E-11"
        iyy="3.4217E-05"
        iyz="6.5947E-11"
        izz="6.4363E-05" />
    </inertial>
    <visual>
      <origin
        xyz="0 0 0"
        rpy="0 0 0" />
      <geometry>
        <mesh
          filename="package://NuevaBaseMetal2/meshes/FR_Link.STL" />
      </geometry>
      <material
        name="">
        <color
          rgba="0.39216 0.41961 0.53333 1" />
      </material>
    </visual>
    <collision>
      <origin
        xyz="0 0 0"
        rpy="0 0 0" />
      <geometry>
        <mesh
          filename="package://NuevaBaseMetal2/meshes/FR_Link.STL" />
      </geometry>
    </collision>
  </link>
  <joint
    name="FR_Joint"
    type="continuous">
    <origin
      xyz="0.20406 -0.20406 0.0185"
      rpy="1.5708 0 0.7854" />
    <parent
      link="Base_link" />
    <child
      link="FR_Link" />
    <axis
      xyz="0 0 -1" />
  </joint>
  <link
    name="Lidar_Link">
    <inertial>
      <origin
        xyz="7.9797E-17 -1.1102E-16 0.063"
        rpy="0 0 0" />
      <mass
        value="0.15394" />
      <inertia
        ixx="6.7669E-05"
        ixy="-1.8808E-37"
        ixz="2.3468E-21"
        iyy="6.7669E-05"
        iyz="-9.2535E-24"
        izz="9.4287E-05" />
    </inertial>
    <visual>
      <origin
        xyz="0 0 0"
        rpy="0 0 0" />
      <geometry>
        <mesh
          filename="package://NuevaBaseMetal2/meshes/Lidar_Link.STL" />
      </geometry>
      <material
        name="">
        <color
          rgba="0.3 0.3 0.3 1" />
      </material>
    </visual>
    <collision>
      <origin
        xyz="0 0 0"
        rpy="0 0 0" />
      <geometry>
        <mesh
          filename="package://NuevaBaseMetal2/meshes/Lidar_Link.STL" />
      </geometry>
    </collision>
  </link>
  <joint
    name="Lidar_Joint"
    type="fixed">
    <origin
      xyz="0 0 0"
      rpy="0 0 0" />
    <parent
      link="Base_link" />
    <child
      link="Lidar_Link" />
    <axis
      xyz="0 0 0" />
  </joint>
  <link
    name="Camera_Link">
    <inertial>
      <origin
        xyz="7.9797E-17 -1.1102E-16 0.063"
        rpy="0 0 0" />
      <mass
        value="0.15394" />
      <inertia
        ixx="6.7669E-05"
        ixy="-1.8808E-37"
        ixz="2.3468E-21"
        iyy="6.7669E-05"
        iyz="-9.2535E-24"
        izz="9.4287E-05" />
    </inertial>
    <visual>
      <origin
        xyz="0 0 0"
        rpy="0 0 0" />
      <geometry>
        <mesh
          filename="package://NuevaBaseMetal2/meshes/Camera_Link.STL" />
      </geometry>
      <material
        name="">
        <color
          rgba="0.1 0.1 0.1 1" />
      </material>
    </visual>
    <collision>
      <origin
        xyz="0 0 0"
        rpy="0 0 0" />
      <geometry>
        <mesh
          filename="package://NuevaBaseMetal2/meshes/Camera_Link.STL" />
      </geometry>
    </collision>
  </link>
  <joint
    name="Camera_Joint"
    type="fixed">
    <origin
      xyz="0 0 0"
      rpy="0 0 0" />
    <parent
      link="Base_link" />
    <child
      link="Camera_Link" />
    <axis
      xyz="0 0 0" />
  </joint>
</robot>